Workbook

Sheet Data
B2: English | C2: Grade 4 | E2: Grade 5 | G2: Grade 6
C3: Quality Report | E3: Quality Report | G3: Quality Report
C4: Average | D4: Participation | E4: Average | F4: Participation | G4: Average | H4: Participation
B5: Pribadi Depok | C5: 79 | D5: 22 | E5: 86 | F5: 20 | G5: 80 | H5: 23 | I5: =IFERROR(__xludf.DUMMYFUNCTION("ROUND(AVERAGE(FILTER({C5,E5,G5,#REF!,#REF!,#REF!},{C5,E5,G5,#REF!,#REF!,#REF!}<>0)),1)"),81.7) -> 81.7
B6: Pribadi Bandung | C6: 77 | D6: 29 | E6: 81 | F6: 30 | G6: 82 | H6: 27 | I6: =IFERROR(__xludf.DUMMYFUNCTION("ROUND(AVERAGE(FILTER({C6,E6,G6,#REF!,#REF!,#REF!},{C6,E6,G6,#REF!,#REF!,#REF!}<>0)),1)"),80.0) -> 80
B7: Kharisma Bangsa | C7: 80 | D7: 38 | E7: 83 | F7: 21 | G7: 88 | H7: 41 | I7: =IFERROR(__xludf.DUMMYFUNCTION("ROUND(AVERAGE(FILTER({C7,E7,G7,#REF!,#REF!,#REF!},{C7,E7,G7,#REF!,#REF!,#REF!}<>0)),1)"),83.7) -> 83.7
B8: Prestige School | C8: 67 | D8: 24 | E8: 74 | F8: 15 | G8: 77 | H8: 16 | I8: =IFERROR(__xludf.DUMMYFUNCTION("ROUND(AVERAGE(FILTER({C8,E8,G8,#REF!,#REF!,#REF!},{C8,E8,G8,#REF!,#REF!,#REF!}<>0)),1)"),72.7) -> 72.7
B9: Semesta 2 | C9: 79 | D9: 52 | E9: 91 | F9: 58 | G9: 85 | H9: 44 | I9: =IFERROR(__xludf.DUMMYFUNCTION("ROUND(AVERAGE(FILTER({C9,E9,G9,#REF!,#REF!,#REF!},{C9,E9,G9,#REF!,#REF!,#REF!}<>0)),1)"),85.0) -> 85
B10: Pribadi Premiere | C10: 85 | D10: 9 | E10: 84 | F10: 19 | G10: 0 | H10: 0 | I10: =IFERROR(__xludf.DUMMYFUNCTION("ROUND(AVERAGE(FILTER({C10,E10,G10,#REF!,#REF!,#REF!},{C10,E10,G10,#REF!,#REF!,#REF!}<>0)),1)"),84.5) -> 84.5
B11: Fatih Bilingual School | C11: 0 | D11: 0 | E11: 0 | F11: 0 | G11: 0 | H11: 0 | I11: 0
B12: TNA Fatih | C12: 0 | D12: 0 | E12: 0 | F12: 0 | G12: 0 | H12: 0 | I12: 0
C13: 78 | D13: 174 | E13: 85 | F13: 163 | G13: 84 | H13: 151
B15: Science | C15: Grade 4 | E15: Grade 5 | G15: Grade 6
C16: Quality Report | E16: Quality Report | G16: Quality Report
C17: Average | D17: Participation | E17: Average | F17: Participation | G17: Average | H17: Participation
B18: Pribadi Depok | C18: 79 | D18: 22 | E18: 73 | F18: 20 | G18: 82 | H18: 23 | I18: =IFERROR(__xludf.DUMMYFUNCTION("ROUND(AVERAGE(FILTER({C18,E18,G18,#REF!,#REF!,#REF!},{C18,E18,G18,#REF!,#REF!,#REF!}<>0)),1)"),78.0) -> 78
B19: Pribadi Bandung | C19: 77 | D19: 29 | E19: 69 | F19: 31 | G19: 76 | H19: 27 | I19: =IFERROR(__xludf.DUMMYFUNCTION("ROUND(AVERAGE(FILTER({C19,E19,G19,#REF!,#REF!,#REF!},{C19,E19,G19,#REF!,#REF!,#REF!}<>0)),1)"),74.0) -> 74
B20: Kharisma Bangsa | C20: 85 | D20: 40 | E20: 77 | F20: 20 | G20: 85 | H20: 41 | I20: =IFERROR(__xludf.DUMMYFUNCTION("ROUND(AVERAGE(FILTER({C20,E20,G20,#REF!,#REF!,#REF!},{C20,E20,G20,#REF!,#REF!,#REF!}<>0)),1)"),82.3) -> 82.3
B21: Prestige School | C21: 74 | D21: 24 | E21: 62 | F21: 15 | G21: 74 | H21: 16 | I21: =IFERROR(__xludf.DUMMYFUNCTION("ROUND(AVERAGE(FILTER({C21,E21,G21,#REF!,#REF!,#REF!},{C21,E21,G21,#REF!,#REF!,#REF!}<>0)),1)"),70.0) -> 70
B22: Semesta 2 | C22: 85 | D22: 51 | E22: 76 | F22: 59 | G22: 82 | H22: 45 | I22: =IFERROR(__xludf.DUMMYFUNCTION("ROUND(AVERAGE(FILTER({C22,E22,G22,#REF!,#REF!,#REF!},{C22,E22,G22,#REF!,#REF!,#REF!}<>0)),1)"),81.0) -> 81
B23: Pribadi Premiere | C23: 87 | D23: 9 | E23: 69 | F23: 19 | G23: 0 | H23: 0 | I23: =IFERROR(__xludf.DUMMYFUNCTION("ROUND(AVERAGE(FILTER({C23,E23,G23,#REF!,#REF!,#REF!},{C23,E23,G23,#REF!,#REF!,#REF!}<>0)),1)"),78.0) -> 78
B24: Fatih Bilingual School | C24: 0 | D24: 0 | E24: 0 | F24: 0 | G24: 0 | H24: 0 | I24: 0
B25: TNA Fatih | C25: 0 | D25: 0 | E25: 0 | F25: 0 | G25: 0 | H25: 0 | I25: 0
C26: 81 | D26: 175 | E26: 72 | F26: 164 | G26: 81 | H26: 152
B28: Mathematics | C28: Grade 4 | E28: Grade 5 | G28: Grade 6
C29: Quality Report | E29: Quality Report | G29: Quality Report
C30: Average | D30: Participation | E30: Average | F30: Participation | G30: Average | H30: Participation
B31: Pribadi Depok | C31: 66 | D31: 22 | E31: 77 | F31: 20 | G31: 83 | H31: 23 | I31: =IFERROR(__xludf.DUMMYFUNCTION("ROUND(AVERAGE(FILTER({C31,E31,G31,#REF!,#REF!,#REF!},{C31,E31,G31,#REF!,#REF!,#REF!}<>0)),1)"),75.3) -> 75.3
B32: Pribadi Bandung | C32: 70 | D32: 28 | E32: 69 | F32: 31 | G32: 81 | H32: 27 | I32: =IFERROR(__xludf.DUMMYFUNCTION("ROUND(AVERAGE(FILTER({C32,E32,G32,#REF!,#REF!,#REF!},{C32,E32,G32,#REF!,#REF!,#REF!}<>0)),1)"),73.3) -> 73.3
B33: Kharisma Bangsa | C33: 80 | D33: 41 | E33: 82 | F33: 19 | G33: 84 | H33: 41 | I33: =IFERROR(__xludf.DUMMYFUNCTION("ROUND(AVERAGE(FILTER({C33,E33,G33,#REF!,#REF!,#REF!},{C33,E33,G33,#REF!,#REF!,#REF!}<>0)),1)"),82.0) -> 82
B34: Prestige School | C34: 64 | D34: 24 | E34: 64 | F34: 15 | G34: 70 | H34: 16 | I34: =IFERROR(__xludf.DUMMYFUNCTION("ROUND(AVERAGE(FILTER({C34,E34,G34,#REF!,#REF!,#REF!},{C34,E34,G34,#REF!,#REF!,#REF!}<>0)),1)"),66.0) -> 66
B35: Semesta 2 | C35: 77 | D35: 52 | E35: 82 | F35: 59 | G35: 86 | H35: 45 | I35: =IFERROR(__xludf.DUMMYFUNCTION("ROUND(AVERAGE(FILTER({C35,E35,G35,#REF!,#REF!,#REF!},{C35,E35,G35,#REF!,#REF!,#REF!}<>0)),1)"),81.7) -> 81.7
B36: Pribadi Premiere | C36: 85 | D36: 9 | E36: 84 | F36: 19 | G36: 0 | H36: 0 | I36: =IFERROR(__xludf.DUMMYFUNCTION("ROUND(AVERAGE(FILTER({C36,E36,G36,#REF!,#REF!,#REF!},{C36,E36,G36,#REF!,#REF!,#REF!}<>0)),1)"),84.5) -> 84.5
B37: Fatih Bilingual School | C37: 0 | D37: 0 | E37: 0 | F37: 0 | G37: 0 | H37: 0 | I37: 0
B38: TNA Fatih | C38: 0 | D38: 0 | E38: 0 | F38: 0 | G38: 0 | H38: 0 | I38: 0
C39: 74 | D39: 176 | E39: 77 | F39: 162 | G39: 83 | H39: 152
B41: Bahasa Indonesia | C41: Grade 4 | E41: Grade 5 | G41: Grade 6
C42: Quality Report | E42: Quality Report | G42: Quality Report
C43: Average | D43: Participation | E43: Average | F43: Participation | G43: Average | H43: Participation
B44: Pribadi Depok | C44: 81 | D44: 20 | E44: 80 | F44: 19 | G44: 80 | H44: 21 | I44: =IFERROR(__xludf.DUMMYFUNCTION("ROUND(AVERAGE(FILTER({C44,E44,G44,#REF!,#REF!,#REF!},{C44,E44,G44,#REF!,#REF!,#REF!}<>0)),1)"),80.3) -> 80.3
...

Sheet Analysis
C1: SD
C2: Grade 4 | D2: Grade 5 | E2: Grade 6 | F2: Average
B3: Pribadi Depok | C3: {=AVERAGEIF({Data!C5,Data!C18,Data!C31,Data!C44,Data!C57},"<>0")} -> 77.6 | D3: {=AVERAGEIF({Data!E5,Data!E18,Data!E31,Data!E44,Data!E57},"<>0")} -> 80.8 | E3: {=AVERAGEIF({Data!G5,Data!G18,Data!G31,Data!G44,Data!G57},"<>0")} -> 83 | F3: =AVERAGEIF(C3:E3,"<>0") -> 80.466667
B4: Pribadi Bandung | C4: {=AVERAGEIF({Data!C6,Data!C19,Data!C32,Data!C45,Data!C58},"<>0")} -> 76 | D4: {=AVERAGEIF({Data!E6,Data!E19,Data!E32,Data!E45,Data!E58},"<>0")} -> 72 | E4: {=AVERAGEIF({Data!G6,Data!G19,Data!G32,Data!G45,Data!G58},"<>0")} -> 80.6 | F4: =AVERAGEIF(C4:E4,"<>0") -> 76.2
B5: Kharisma Bangsa | C5: {=AVERAGEIF({Data!C7,Data!C20,Data!C33,Data!C46,Data!C59},"<>0")} -> 80.4 | D5: {=AVERAGEIF({Data!E7,Data!E20,Data!E33,Data!E46,Data!E59},"<>0")} -> 80.4 | E5: {=AVERAGEIF({Data!G7,Data!G20,Data!G33,Data!G46,Data!G59},"<>0")} -> 85.4 | F5: =AVERAGEIF(C5:E5,"<>0") -> 82.066667
B6: Prestige School | C6: {=AVERAGEIF({Data!C8,Data!C21,Data!C34,Data!C47,Data!C60},"<>0")} -> 71.6 | D6: {=AVERAGEIF({Data!E8,Data!E21,Data!E34,Data!E47,Data!E60},"<>0")} -> 70.6 | E6: {=AVERAGEIF({Data!G8,Data!G21,Data!G34,Data!G47,Data!G60},"<>0")} -> 75.6 | F6: =AVERAGEIF(C6:E6,"<>0") -> 72.6
B7: Semesta 2 | C7: {=AVERAGEIF({Data!C9,Data!C22,Data!C35,Data!C48,Data!C61},"<>0")} -> 82.2 | D7: {=AVERAGEIF({Data!E9,Data!E22,Data!E35,Data!E48,Data!E61},"<>0")} -> 85.2 | E7: {=AVERAGEIF({Data!G9,Data!G22,Data!G35,Data!G48,Data!G61},"<>0")} -> 84.6 | F7: =AVERAGEIF(C7:E7,"<>0") -> 84
B8: Pribadi Premiere | C8: {=AVERAGEIF({Data!C10,Data!C23,Data!C36,Data!C49,Data!C62},"<>0")} -> 87 | D8: {=AVERAGEIF({Data!E10,Data!E23,Data!E36,Data!E49,Data!E62},"<>0")} -> 80.8 | E8: 0 | F8: =AVERAGEIF(C8:E8,"<>0") -> 83.9
B9: Fatih Bilingual School | C9: 0 | D9: 0 | E9: 0 | F9: 0
B10: TNA Fatih | C10: 0 | D10: 0 | E10: 0 | F10: 0
C11: =AVERAGEIF(C3:C10,"<>0") -> 79.133333 | D11: =AVERAGEIF(D3:D10,"<>0") -> 78.3 | E11: =AVERAGEIF(E3:E10,"<>0") -> 81.84 | F11: =AVERAGEIF(F3:F10,"<>0") -> 79.872222
