Workbook

Sheet Data
B2: English | C2: Grade 4 | E2: Grade 5
C3: Quality Report | E3: Quality Report
C4: Average | D4: Participation | E4: Average | F4: Participation
B5: Pribadi Depok | C5: 84.91 | D5: 22 | E5: 86 | F5: 18 | G5: =IFERROR(__xludf.DUMMYFUNCTION("ROUND(AVERAGE(FILTER({C5,E5,#REF!,#REF!,#REF!,#REF!},{C5,E5,#REF!,#REF!,#REF!,#REF!}<>0)),1)"),85.5) -> 85.5
B6: Pribadi Bandung | C6: 88.14 | D6: 28 | E6: 78.13 | F6: 30 | G6: =IFERROR(__xludf.DUMMYFUNCTION("ROUND(AVERAGE(FILTER({C6,E6,#REF!,#REF!,#REF!,#REF!},{C6,E6,#REF!,#REF!,#REF!,#REF!}<>0)),1)"),83.1) -> 83.1
B7: Kharisma Bangsa | C7: 91.44 | D7: 43 | E7: 87.4 | F7: 20 | G7: =IFERROR(__xludf.DUMMYFUNCTION("ROUND(AVERAGE(FILTER({C7,E7,#REF!,#REF!,#REF!,#REF!},{C7,E7,#REF!,#REF!,#REF!,#REF!}<>0)),1)"),89.4) -> 89.4
B8: Prestige School | C8: 72.17 | D8: 24 | E8: 72 | F8: 15 | G8: =IFERROR(__xludf.DUMMYFUNCTION("ROUND(AVERAGE(FILTER({C8,E8,#REF!,#REF!,#REF!,#REF!},{C8,E8,#REF!,#REF!,#REF!,#REF!}<>0)),1)"),72.1) -> 72.1
B9: Semesta 2 | C9: 88.74 | D9: 54 | E9: 84 | F9: 58 | G9: =IFERROR(__xludf.DUMMYFUNCTION("ROUND(AVERAGE(FILTER({C9,E9,#REF!,#REF!,#REF!,#REF!},{C9,E9,#REF!,#REF!,#REF!,#REF!}<>0)),1)"),86.4) -> 86.4
B10: Pribadi Premiere | C10: 86.22 | D10: 9 | E10: 86.44 | F10: 18 | G10: =IFERROR(__xludf.DUMMYFUNCTION("ROUND(AVERAGE(FILTER({C10,E10,#REF!,#REF!,#REF!,#REF!},{C10,E10,#REF!,#REF!,#REF!,#REF!}<>0)),1)"),86.3) -> 86.3
B11: Fatih Bilingual School | C11: 77.26 | D11: 19 | E11: 76.8 | F11: 10 | G11: =IFERROR(__xludf.DUMMYFUNCTION("ROUND(AVERAGE(FILTER({C11,E11,#REF!,#REF!,#REF!,#REF!},{C11,E11,#REF!,#REF!,#REF!,#REF!}<>0)),1)"),77.0) -> 77
B12: TNA Fatih | C12: 65.14 | D12: 21 | E12: 72.71 | F12: 17 | G12: =IFERROR(__xludf.DUMMYFUNCTION("ROUND(AVERAGE(FILTER({C12,E12,#REF!,#REF!,#REF!,#REF!},{C12,E12,#REF!,#REF!,#REF!,#REF!}<>0)),1)"),68.9) -> 68.9
D13: =SUM(D5:D12) -> 220 | E13: 80.44 | F13: =SUM(F5:F12) -> 186
B15: Science | C15: Grade 4 | E15: Grade 5
C16: Quality Report | E16: Quality Report
C17: Average | D17: Participation | E17: Average | F17: Participation
B18: Pribadi Depok | C18: 80.36 | D18: 22 | E18: 83.58 | F18: 19 | G18: =IFERROR(__xludf.DUMMYFUNCTION("ROUND(AVERAGE(FILTER({C18,E18,#REF!,#REF!,#REF!,#REF!},{C18,E18,#REF!,#REF!,#REF!,#REF!}<>0)),1)"),82.0) -> 82
B19: Pribadi Bandung | C19: 78.34 | D19: 29 | E19: 73.66 | F19: 29 | G19: =IFERROR(__xludf.DUMMYFUNCTION("ROUND(AVERAGE(FILTER({C19,E19,#REF!,#REF!,#REF!,#REF!},{C19,E19,#REF!,#REF!,#REF!,#REF!}<>0)),1)"),76.0) -> 76
B20: Kharisma Bangsa | C20: 83.35 | D20: 43 | E20: 87 | F20: 20 | G20: =IFERROR(__xludf.DUMMYFUNCTION("ROUND(AVERAGE(FILTER({C20,E20,#REF!,#REF!,#REF!,#REF!},{C20,E20,#REF!,#REF!,#REF!,#REF!}<>0)),1)"),85.2) -> 85.2
B21: Prestige School | C21: 66.17 | D21: 24 | E21: 74.4 | F21: 15 | G21: =IFERROR(__xludf.DUMMYFUNCTION("ROUND(AVERAGE(FILTER({C21,E21,#REF!,#REF!,#REF!,#REF!},{C21,E21,#REF!,#REF!,#REF!,#REF!}<>0)),1)"),70.3) -> 70.3
B22: Semesta 2 | C22: 81.26 | D22: 54 | E22: 85.61 | F22: 57 | G22: =IFERROR(__xludf.DUMMYFUNCTION("ROUND(AVERAGE(FILTER({C22,E22,#REF!,#REF!,#REF!,#REF!},{C22,E22,#REF!,#REF!,#REF!,#REF!}<>0)),1)"),83.4) -> 83.4
B23: Pribadi Premiere | C23: 90 | D23: 8 | E23: 82.67 | F23: 18 | G23: =IFERROR(__xludf.DUMMYFUNCTION("ROUND(AVERAGE(FILTER({C23,E23,#REF!,#REF!,#REF!,#REF!},{C23,E23,#REF!,#REF!,#REF!,#REF!}<>0)),1)"),86.3) -> 86.3
B24: Fatih Bilingual School | C24: 69.47 | D24: 19 | E24: 77.82 | F24: 11 | G24: =IFERROR(__xludf.DUMMYFUNCTION("ROUND(AVERAGE(FILTER({C24,E24,#REF!,#REF!,#REF!,#REF!},{C24,E24,#REF!,#REF!,#REF!,#REF!}<>0)),1)"),73.6) -> 73.6
B25: TNA Fatih | C25: 66.48 | D25: 21 | E25: 79.29 | F25: 17 | G25: =IFERROR(__xludf.DUMMYFUNCTION("ROUND(AVERAGE(FILTER({C25,E25,#REF!,#REF!,#REF!,#REF!},{C25,E25,#REF!,#REF!,#REF!,#REF!}<>0)),1)"),72.9) -> 72.9
C26: 76.93 | D26: =SUM(D18:D25) -> 220 | E26: 80.5 | F26: =SUM(F18:F25) -> 186
B28: Mathematics | C28: Grade 4 | E28: Grade 5
C29: Quality Report | E29: Quality Report
C30: Average | D30: Participation | E30: Average | F30: Participation
B31: Pribadi Depok | C31: 81.82 | D31: 22 | E31: 79.37 | F31: 19 | G31: =IFERROR(__xludf.DUMMYFUNCTION("ROUND(AVERAGE(FILTER({C31,E31,#REF!,#REF!,#REF!,#REF!},{C31,E31,#REF!,#REF!,#REF!,#REF!}<>0)),1)"),80.6) -> 80.6
B32: Pribadi Bandung | C32: 78.57 | D32: 28 | E32: 70.71 | F32: 31 | G32: =IFERROR(__xludf.DUMMYFUNCTION("ROUND(AVERAGE(FILTER({C32,E32,#REF!,#REF!,#REF!,#REF!},{C32,E32,#REF!,#REF!,#REF!,#REF!}<>0)),1)"),74.6) -> 74.6
B33: Kharisma Bangsa | C33: 83.16 | D33: 43 | E33: 85.6 | F33: 20 | G33: =IFERROR(__xludf.DUMMYFUNCTION("ROUND(AVERAGE(FILTER({C33,E33,#REF!,#REF!,#REF!,#REF!},{C33,E33,#REF!,#REF!,#REF!,#REF!}<>0)),1)"),84.4) -> 84.4
B34: Prestige School | C34: 68.5 | D34: 24 | E34: 61.87 | F34: 15 | G34: =IFERROR(__xludf.DUMMYFUNCTION("ROUND(AVERAGE(FILTER({C34,E34,#REF!,#REF!,#REF!,#REF!},{C34,E34,#REF!,#REF!,#REF!,#REF!}<>0)),1)"),65.2) -> 65.2
B35: Semesta 2 | C35: 85.11 | D35: 54 | E35: 87.66 | F35: 58 | G35: =IFERROR(__xludf.DUMMYFUNCTION("ROUND(AVERAGE(FILTER({C35,E35,#REF!,#REF!,#REF!,#REF!},{C35,E35,#REF!,#REF!,#REF!,#REF!}<>0)),1)"),86.4) -> 86.4
B36: Pribadi Premiere | C36: 91.5 | D36: 8 | E36: 82.74 | F36: 19 | G36: =IFERROR(__xludf.DUMMYFUNCTION("ROUND(AVERAGE(FILTER({C36,E36,#REF!,#REF!,#REF!,#REF!},{C36,E36,#REF!,#REF!,#REF!,#REF!}<>0)),1)"),87.1) -> 87.1
B37: Fatih Bilingual School | C37: 74.53 | D37: 19 | E37: 74.91 | F37: 11 | G37: =IFERROR(__xludf.DUMMYFUNCTION("ROUND(AVERAGE(FILTER({C37,E37,#REF!,#REF!,#REF!,#REF!},{C37,E37,#REF!,#REF!,#REF!,#REF!}<>0)),1)"),74.7) -> 74.7
B38: TNA Fatih | C38: 65.27 | D38: 22 | E38: 90.67 | F38: 18 | G38: =IFERROR(__xludf.DUMMYFUNCTION("ROUND(AVERAGE(FILTER({C38,E38,#REF!,#REF!,#REF!,#REF!},{C38,E38,#REF!,#REF!,#REF!,#REF!}<>0)),1)"),78.0) -> 78
C39: 78.56 | D39: =SUM(D31:D38) -> 220 | E39: 79.19 | F39: =SUM(F31:F38) -> 191
B41: Bahasa Indonesia | C41: Grade 4 | E41: Grade 5
C42: Quality Report | E42: Quality Report
C43: Average | D43: Participation | E43: Average | F43: Participation
B44: Pribadi Depok | C44: 84.18 | D44: 22 | E44: 82.67 | F44: 18 | G44: =IFERROR(__xludf.DUMMYFUNCTION("ROUND(AVERAGE(FILTER({C44,E44,#REF!,#REF!,#REF!,#REF!},{C44,E44,#REF!,#REF!,#REF!,#REF!}<>0)),1)"),83.4) -> 83.4
...

Sheet Analysis
C1: SD
C2: Grade 4 | D2: Grade 5 | E2: Average
B3: Pribadi Depok | C3: {=AVERAGEIF({Data!C5,Data!C18,Data!C31,Data!C44,Data!C57},"<>0")} -> 79.904 | D3: {=AVERAGEIF({Data!E5,Data!E18,Data!E31,Data!E44,Data!E57},"<>0")} -> 83.462 | E3: =AVERAGEIF(C3:D3,"<>0") -> 81.683
B4: Pribadi Bandung | C4: {=AVERAGEIF({Data!C6,Data!C19,Data!C32,Data!C45,Data!C58},"<>0")} -> 78.368 | D4: {=AVERAGEIF({Data!E6,Data!E19,Data!E32,Data!E45,Data!E58},"<>0")} -> 74.022 | E4: =AVERAGEIF(C4:D4,"<>0") -> 76.195
B5: Kharisma Bangsa | C5: {=AVERAGEIF({Data!C7,Data!C20,Data!C33,Data!C46,Data!C59},"<>0")} -> 81.436 | D5: {=AVERAGEIF({Data!E7,Data!E20,Data!E33,Data!E46,Data!E59},"<>0")} -> 84.976 | E5: =AVERAGEIF(C5:D5,"<>0") -> 83.206
B6: Prestige School | C6: {=AVERAGEIF({Data!C8,Data!C21,Data!C34,Data!C47,Data!C60},"<>0")} -> 67.508 | D6: {=AVERAGEIF({Data!E8,Data!E21,Data!E34,Data!E47,Data!E60},"<>0")} -> 75.734 | E6: =AVERAGEIF(C6:D6,"<>0") -> 71.621
B7: Semesta 2 | C7: {=AVERAGEIF({Data!C9,Data!C22,Data!C35,Data!C48,Data!C61},"<>0")} -> 81.85 | D7: {=AVERAGEIF({Data!E9,Data!E22,Data!E35,Data!E48,Data!E61},"<>0")} -> 86.902 | E7: =AVERAGEIF(C7:D7,"<>0") -> 84.376
B8: Pribadi Premiere | C8: {=AVERAGEIF({Data!C10,Data!C23,Data!C36,Data!C49,Data!C62},"<>0")} -> 87.782 | D8: {=AVERAGEIF({Data!E10,Data!E23,Data!E36,Data!E49,Data!E62},"<>0")} -> 85.24 | E8: =AVERAGEIF(C8:D8,"<>0") -> 86.511
B9: Fatih Bilingual School | C9: {=AVERAGEIF({Data!C11,Data!C24,Data!C37,Data!C50,Data!C63},"<>0")} -> 75.082 | D9: {=AVERAGEIF({Data!E11,Data!E24,Data!E37,Data!E50,Data!E63},"<>0")} -> 82.148 | E9: =AVERAGEIF(C9:D9,"<>0") -> 78.615
B10: TNA Fatih | C10: {=AVERAGEIF({Data!C12,Data!C25,Data!C38,Data!C51,Data!C64},"<>0")} -> 70.366 | D10: {=AVERAGEIF({Data!E12,Data!E25,Data!E38,Data!E51,Data!E64},"<>0")} -> 83.778 | E10: =AVERAGEIF(C10:D10,"<>0") -> 77.072
C11: =AVERAGEIF(C3:C10,"<>0") -> 77.787 | D11: =AVERAGEIF(D3:D10,"<>0") -> 82.03275 | E11: =AVERAGEIF(E3:E10,"<>0") -> 79.909875
